Workbook
Name Cash_minimum: 'CF Realisasi new'!$B$7
Name Cash_minimum: 'CF Realisasi'!$B$7

Sheet Graph
A1: JUMAT | B1: SABTU | C1: MINGGU | D1: SENIN | E1: SELASA | F1: RABU | G1: KAMIS | H1: JUMAT | I1: SABTU | J1: MINGGU | K1: SENIN | L1: SELASA | M1: RABU | N1: KAMIS | O1: JUMAT | P1: SABTU
A2: 45947 | B2: 45948 | C2: 45949 | D2: 45950 | E2: 45951 | F2: 45952 | G2: 45953 | H2: 45954 | I2: 45955 | J2: 45956 | K2: 45957 | L2: 45958 | M2: 45959 | N2: 45960 | O2: 45961 | P2: 45962
A3: ='CF Realisasi new'!C10 -> -1.4106224e+08 | B3: ='CF Realisasi new'!D10 -> -1.4106224e+08 | C3: ='CF Realisasi new'!E10 -> -1.4106224e+08 | D3: ='CF Realisasi new'!F10 -> 6.7873954e+08 | E3: ='CF Realisasi new'!G10 -> -6.2786446e+08 | F3: ='CF Realisasi new'!H10 -> -4.1149744e+08 | G3: ='CF Realisasi new'!I10 -> -1.111319e+09 | H3: ='CF Realisasi new'!J10 -> -2.2747996e+08 | ... P3: ='CF Realisasi new'!R10 -> 3.5587354e+09
D30: Blm minus tp perlu waspada | G30: Blm minus tp perlu waspada

Sheet CF Realisasi
A1: Cash Flow Realization
A2: PT. Werkudara Nirwana Sakti
A6: Period | B6: 45778
A7: Cash balance alert minimum | B7: 200000000
A8: Updated on | B8: 45823 | C8: Minggu | D8: Senin | E8: Selasa | F8: Rabu | G8: Kamis | H8: Jumat | I8: Sabtu | J8: Minggu | K8: Senin | L8: Selasa | M8: Rabu | N8: Kamis | O8: Jumat | P8: Sabtu | Q8: Minggu | R8: Senin | S8: Selasa | T8: Rabu | U8: Kamis | V8: Jumat | W8: Sabtu | X8: Minggu | Y8: Senin | Z8: Selasa | AA8: Rabu | AB8: Kamis | AC8: Jumat | AD8: Sabtu | AE8: Minggu | AF8: Senin | AG8: Selasa | AH8: Rabu | AI8: Kamis | AJ8: Jumat | AK8: Sabtu | AL8: Minggu | AM8: Senin | AN8: Selasa | AO8: Rabu | AP8: Kamis | AQ8: Jumat | AR8: Sabtu | AS8: Minggu | AT8: Senin | AU8: Selasa | AV8: Rabu | AW8: Kamis | AX8: Jumat
B9: Beginning | C9: 45823 | D9: 45824 | E9: 45825 | F9: 45826 | G9: 45827 | H9: 45828 | I9: 45829 | J9: 45830 | K9: 45831 | L9: 45832 | M9: 45833 | N9: 45834 | O9: 45835 | P9: 45836 | Q9: 45837 | R9: 45838 | S9: 45839 | T9: 45840 | U9: 45841 | V9: 45842 | W9: 45843 | X9: 45844 | Y9: 45845 | Z9: 45846 | AA9: 45847 | AB9: 45848 | AC9: 45849 | AD9: 45850 | AE9: 45851 | AF9: 45852 | AG9: 45853 | AH9: 45854 | AI9: 45855 | AJ9: 45856 | AK9: 45857 | AL9: 45858 | AM9: 45859 | AN9: 45860 | AO9: 45861 | AP9: 45862 | AQ9: 45863 | AR9: 45864 | AS9: 45865 | AT9: 45866 | AU9: 45867 | AV9: 45868 | AW9: 45869 | AX9: 45870 | AY9: TOTAL
A10: Cash on hand (beginning of month) CF.9 | B10: =#REF! -> #REF! | C10: =B10 -> #REF! | D10: =(C10+D16)-D32 -> #REF! | E10: =(D10+E16)-E32 -> #REF! | F10: =(E10+F16)-F32 -> #REF! | G10: =(F10+G16)-G32 -> #REF! | H10: =(G10+H16)-H32 -> #REF! | I10: =(H10+I16)-I32 -> #REF! | J10: =(I10+J16)-J32 -> #REF! | K10: =(J10+K16)-K32 -> #REF! | ... AX10: =(AW10+AX16)-AX32 -> #REF! | AY10: =SUM(B10:B10:AY10) -> #REF!
A12: PENERIMAAN CASH | AY12: =SUM(B12:B12:AY12) -> 0
A13: Piutang & Revenue | B13: CF.1 | C13: ='IN-ACC-Piutang & Revenue'!#REF! -> #REF! | D13: ='IN-ACC-Piutang & Revenue'!#REF! -> #REF! | E13: ='IN-ACC-Piutang & Revenue'!#REF! -> #REF! | F13: ='IN-ACC-Piutang & Revenue'!#REF! -> #REF! | G13: ='IN-ACC-Piutang & Revenue'!#REF! -> #REF! | H13: ='IN-ACC-Piutang & Revenue'!#REF! -> #REF! | I13: ='IN-ACC-Piutang & Revenue'!#REF! -> #REF! | J13: ='IN-ACC-Piutang & Revenue'!#REF! -> #REF! | ... AX13: ='IN-ACC-Piutang & Revenue'!#REF! -> #REF! | AY13: =SUM(C13:AX13) -> #REF!
A14: Penerimaan Pengembalian Pinjaman | B14: CF.11 | C14: ='IN-CFC-Penerimaan PengemPinj'!#REF! -> #REF! | D14: ='IN-CFC-Penerimaan PengemPinj'!#REF! -> #REF! | E14: ='IN-CFC-Penerimaan PengemPinj'!#REF! -> #REF! | F14: ='IN-CFC-Penerimaan PengemPinj'!#REF! -> #REF! | G14: ='IN-CFC-Penerimaan PengemPinj'!#REF! -> #REF! | H14: ='IN-CFC-Penerimaan PengemPinj'!#REF! -> #REF! | I14: ='IN-CFC-Penerimaan PengemPinj'!#REF! -> #REF! | J14: ='IN-CFC-Penerimaan PengemPinj'!#REF! -> #REF! | ... AX14: ='IN-CFC-Penerimaan PengemPinj'!#REF! -> #REF! | AY14: =SUM(C14:AX14) -> #REF!
A15: Suntikan Modal | C15: ='IN-CFC-Suntikan Modal'!#REF! -> #REF! | D15: ='IN-CFC-Suntikan Modal'!#REF! -> #REF! | E15: ='IN-CFC-Suntikan Modal'!#REF! -> #REF! | F15: ='IN-CFC-Suntikan Modal'!#REF! -> #REF! | G15: ='IN-CFC-Suntikan Modal'!#REF! -> #REF! | H15: ='IN-CFC-Suntikan Modal'!#REF! -> #REF! | I15: ='IN-CFC-Suntikan Modal'!#REF! -> #REF! | J15: ='IN-CFC-Suntikan Modal'!#REF! -> #REF! | ... AX15: ='IN-CFC-Suntikan Modal'!#REF! -> #REF! | AY15: =SUM(C15:AX15) -> #REF!
A16: TOTAL CASH RECEIPTS | D16: =SUM(D13:D15) -> #REF! | E16: =SUM(E13:E15) -> #REF! | F16: =SUM(F13:F15) -> #REF! | G16: =SUM(G13:G15) -> #REF! | H16: =SUM(H13:H15) -> #REF! | I16: =SUM(I13:I15) -> #REF! | J16: =SUM(J13:J15) -> #REF! | K16: =SUM(K13:K15) -> #REF! | ... AX16: =SUM(AX13:AX15) -> #REF! | AY16: =SUM(D16:AX16) -> #REF!
A18: CASH PAID OUT | AY18: =SUM(B18:B18:AY18) -> 0
A19: Pajak | B19: CF.10 | C19: ='OUT-ACC-PAJAK'!#REF! -> #REF! | D19: ='OUT-ACC-PAJAK'!#REF! -> #REF! | E19: ='OUT-ACC-PAJAK'!#REF! -> #REF! | F19: ='OUT-ACC-PAJAK'!#REF! -> #REF! | G19: ='OUT-ACC-PAJAK'!#REF! -> #REF! | H19: ='OUT-ACC-PAJAK'!#REF! -> #REF! | I19: ='OUT-ACC-PAJAK'!#REF! -> #REF! | J19: ='OUT-ACC-PAJAK'!#REF! -> #REF! | ... AX19: ='OUT-ACC-PAJAK'!#REF! -> #REF! | AY19: =SUM(C19:AX19) -> #REF!
A20: Gaji & Benefid Karyawan | B20: CF.3 | C20: ='OUT - HR - Gaji & Benefit'!#REF! -> #REF! | D20: ='OUT - HR - Gaji & Benefit'!#REF! -> #REF! | E20: ='OUT - HR - Gaji & Benefit'!#REF! -> #REF! | F20: ='OUT - HR - Gaji & Benefit'!#REF! -> #REF! | G20: ='OUT - HR - Gaji & Benefit'!#REF! -> #REF! | H20: ='OUT - HR - Gaji & Benefit'!#REF! -> #REF! | I20: ='OUT - HR - Gaji & Benefit'!#REF! -> #REF! | J20: ='OUT - HR - Gaji & Benefit'!#REF! -> #REF! | ... AX20: ='OUT - HR - Gaji & Benefit'!#REF! -> #REF! | AY20: =SUM(C20:AX20) -> #REF!
A21: Corporate Expenses | B21: CF.6 | C21: ='OUT - CFC - Corporate Expenses'!#REF! -> #REF! | D21: ='OUT - CFC - Corporate Expenses'!#REF! -> #REF! | E21: ='OUT - CFC - Corporate Expenses'!#REF! -> #REF! | F21: ='OUT - CFC - Corporate Expenses'!#REF! -> #REF! | G21: ='OUT - CFC - Corporate Expenses'!#REF! -> #REF! | H21: ='OUT - CFC - Corporate Expenses'!#REF! -> #REF! | I21: ='OUT - CFC - Corporate Expenses'!#REF! -> #REF! | J21: ='OUT - CFC - Corporate Expenses'!#REF! -> #REF! | ... AX21: ='OUT - CFC - Corporate Expenses'!#REF! -> #REF! | AY21: =SUM(C21:AX21) -> #REF!
A22: Operational Kantor (GA) | B22: CF.7 | C22: ='OUT - ACC - Ops Kantor'!#REF! -> #REF! | D22: ='OUT - ACC - Ops Kantor'!#REF! -> #REF! | E22: ='OUT - ACC - Ops Kantor'!#REF! -> #REF! | F22: ='OUT - ACC - Ops Kantor'!#REF! -> #REF! | G22: ='OUT - ACC - Ops Kantor'!#REF! -> #REF! | H22: ='OUT - ACC - Ops Kantor'!#REF! -> #REF! | I22: ='OUT - ACC - Ops Kantor'!#REF! -> #REF! | J22: ='OUT - ACC - Ops Kantor'!#REF! -> #REF! | ... AX22: ='OUT - ACC - Ops Kantor'!#REF! -> #REF! | AY22: =SUM(C22:AX22) -> #REF!
A23: Operational All Departemen | B23: CF.12 | C23: ='OUT - CF.12 Ops All Dept'!DT80 -> 0 | D23: ='OUT - CF.12 Ops All Dept'!DU80 -> 0 | E23: ='OUT - CF.12 Ops All Dept'!DV80 -> 0 | F23: ='OUT - CF.12 Ops All Dept'!DW80 -> 0 | G23: ='OUT - CF.12 Ops All Dept'!DX80 -> 0 | H23: ='OUT - CF.12 Ops All Dept'!DY80 -> 0 | I23: ='OUT - CF.12 Ops All Dept'!DZ80 -> 0 | J23: ='OUT - CF.12 Ops All Dept'!EA80 -> 0 | ... AX23: ='OUT - CF.12 Ops All Dept'!FO80 -> 2500000 | AY23: =SUM(C23:AX23) -> 196649062
A24: Bunga & Angsuran | B24: CF.5 | C24: ='OUT - CFC - Bunga & Angsuran'!DX15 -> 0 | D24: ='OUT - CFC - Bunga & Angsuran'!DY15 -> 0 | E24: ='OUT - CFC - Bunga & Angsuran'!DZ15 -> 0 | F24: ='OUT - CFC - Bunga & Angsuran'!EA15 -> 0 | G24: ='OUT - CFC - Bunga & Angsuran'!EB15 -> 0 | H24: ='OUT - CFC - Bunga & Angsuran'!EC15 -> 0 | I24: ='OUT - CFC - Bunga & Angsuran'!ED15 -> 0 | J24: ='OUT - CFC - Bunga & Angsuran'!EE15 -> 0 | ... AX24: ='OUT - CFC - Bunga & Angsuran'!FS15 -> 0 | AY24: =SUM(C24:AX24) -> 0
A25: Cost Of Revenue | B25: CF.2 | C25: ='OUT - TEP - Cost Of Revenue'!#REF! -> #REF! | D25: ='OUT - TEP - Cost Of Revenue'!#REF! -> #REF! | E25: ='OUT - TEP - Cost Of Revenue'!#REF! -> #REF! | F25: ='OUT - TEP - Cost Of Revenue'!#REF! -> #REF! | G25: ='OUT - TEP - Cost Of Revenue'!#REF! -> #REF! | H25: ='OUT - TEP - Cost Of Revenue'!#REF! -> #REF! | I25: ='OUT - TEP - Cost Of Revenue'!#REF! -> #REF! | J25: ='OUT - TEP - Cost Of Revenue'!#REF! -> #REF! | ... AX25: ='OUT - TEP - Cost Of Revenue'!#REF! -> #REF! | AY25: =SUM(C25:AX25) -> #REF!
A26: Hutang Usaha | B26: CF.4 | C26: ='OUT - CFC - Hutang Usaha'!#REF! -> #REF! | D26: ='OUT - CFC - Hutang Usaha'!#REF! -> #REF! | E26: ='OUT - CFC - Hutang Usaha'!DX102 -> 0 | F26: ='OUT - CFC - Hutang Usaha'!DY102 -> 0 | G26: ='OUT - CFC - Hutang Usaha'!DZ102 -> 0 | H26: ='OUT - CFC - Hutang Usaha'!EA102 -> 0 | I26: ='OUT - CFC - Hutang Usaha'!EB102 -> 0 | J26: ='OUT - CFC - Hutang Usaha'!EC102 -> 0 | K26: ='OUT - CFC - Hutang Usaha'!ED102 -> 0 | L26: ='OUT - CFC - Hutang Usaha'!EE102 -> 0 | ... AX26: ='OUT - CFC - Hutang Usaha'!FQ102 -> 0 | AY26: =SUM(C26:AX26) -> #REF!
A27: Pemberian Pinjaman | B27: CF.8 | AY27: =SUM(C27:AX27) -> 0
A28: Sales Call | B28: CF.9 | AY28: =SUM(C28:AX28) -> 0
A29: Pengembalian Suntikan Modal dari Owner | B29: CF.11 | AY29: =SUM(C29:AX29) -> 0
AY30: =SUM(C30:AX30) -> 0
AY31: =SUM(C31:AX31) -> 0
A32: SUBTOTAL CASH PAID OUT | D32: =SUM(D19:D31) -> #REF! | E32: =SUM(E19:E31) -> #REF! | F32: =SUM(F19:F31) -> #REF! | G32: =SUM(G19:G31) -> #REF! | H32: =SUM(H19:H31) -> #REF! | I32: =SUM(I19:I31) -> #REF! | J32: =SUM(J19:J31) -> #REF! | K32: =SUM(K19:K31) -> #REF! | ... AY32: =SUM(AY19:AY31) -> #REF!
AY33: =SUM(C33:AX33) -> 0
A34: Pengembalian Pinjaman Pokok Modal | AY34: =SUM(C34:AX34) -> 0
A35: Pembelanjaan Modal (Capital Expenditures) | AY35: =SUM(C35:AX35) -> 0
A36: Investasi Usaha Lain (Other startup costs) | AY36: =SUM(C36:AX36) -> 0
A37: Pemberian Pinjaman (Capital Loan) | AY37: =SUM(C37:AX37) -> 0
A38: Prive Penarikan Modal (Owners' withdrawal) | AY38: =SUM(C38:AX38) -> 0
A39: Pembayaran Hutang Usaha (EVENT & TOUR) | AY39: =SUM(C39:AX39) -> 0
A40: Pengembalian Suntikan Modal dari Owner | AY40: =SUM(C40:AX40) -> 0
A41: TOTAL CASH PAID OUT | AY41: =SUM(B41:B41:AY41) -> 0
A43: OTHER OPERATING DATA | AY43: =SUM(B43:B43:AY43) -> 0
A44: Sales Revenue | AY44: =SUM(C44:AX44) -> 0
A45: Accounts receivable balance | AY45: =SUM(C45:AX45) -> 0
A46: Bad debt balance | AY46: =SUM(C46:AX46) -> 0
...

Sheet CF Realisasi new
A1: Cash Flow Realization
A2: PT. Werkudara Nirwana Sakti
A6: Period | B6: 45931
A7: Cash balance alert minimum | B7: 200000000
A8: Updated on | B8: 45947 | C8: JUMAT | D8: SABTU | E8: MINGGU | F8: SENIN | G8: SELASA | H8: RABU | I8: KAMIS | J8: JUMAT | K8: SABTU | L8: MINGGU | M8: SENIN | N8: SELASA | O8: RABU | P8: KAMIS | Q8: JUMAT | R8: SABTU
B9: Beginning | C9: 45947 | D9: 45948 | E9: 45949 | F9: 45950 | G9: 45951 | H9: 45952 | I9: 45953 | J9: 45954 | K9: 45955 | L9: 45956 | M9: 45957 | N9: 45958 | O9: 45959 | P9: 45960 | Q9: 45961 | R9: 45962 | S9: TOTAL
A10: Cash on hand (beginning of month) CF.9 | B10: 750000000 | C10: =B10+C16-C42 -> -1.4106224e+08 | D10: =C10+D16-D42 -> -1.4106224e+08 | E10: =D10+E16-E42 -> -1.4106224e+08 | F10: =E10+F16-F42 -> 6.7873954e+08 | G10: =F10+G16-G42 -> -6.2786446e+08 | H10: =G10+H16-H42 -> -4.1149744e+08 | I10: =H10+I16-I42 -> -1.111319e+09 | J10: =I10+J16-J42 -> -2.2747996e+08 | ... R10: =Q10+R16-R42 -> 3.5587354e+09
A12: TOTAL PENERIMAAN KAS | S12: =SUM(B12:B12:S12) -> 0
A13: Piutang & Revenue | B13: ACC | C13: ='IN-ACC-Piutang & Revenue'!E51 -> 0 | D13: ='IN-ACC-Piutang & Revenue'!F51 -> 0 | E13: ='IN-ACC-Piutang & Revenue'!G51 -> 0 | F13: ='IN-ACC-Piutang & Revenue'!H51 -> 838451777 | G13: ='IN-ACC-Piutang & Revenue'!I51 -> 120390000 | H13: ='IN-ACC-Piutang & Revenue'!J51 -> 291003015 | I13: ='IN-ACC-Piutang & Revenue'!K51 -> 5134305 | J13: ='IN-ACC-Piutang & Revenue'!L51 -> 885839057 | ... R13: ='IN-ACC-Piutang & Revenue'!T51 -> 3787621882 | S13: =SUM(C13:R13) -> 7133738712
A14: Penerimaan Pengembalian Pinjaman | B14: CFC | C14: ='IN-CFC-Penerimaan PengemPinj'!D19 -> 0 | D14: ='IN-CFC-Penerimaan PengemPinj'!E19 -> 0 | E14: ='IN-CFC-Penerimaan PengemPinj'!F19 -> 0 | F14: ='IN-CFC-Penerimaan PengemPinj'!G19 -> 0 | G14: ='IN-CFC-Penerimaan PengemPinj'!H19 -> 0 | H14: ='IN-CFC-Penerimaan PengemPinj'!I19 -> 0 | I14: ='IN-CFC-Penerimaan PengemPinj'!J19 -> 0 | J14: ='IN-CFC-Penerimaan PengemPinj'!K19 -> 0 | ... R14: ='IN-CFC-Penerimaan PengemPinj'!S19 -> 0 | S14: =SUM(C14:R14) -> 0
A15: Suntikan Modal | C15: ='IN-CFC-Suntikan Modal'!D12 -> 0 | D15: ='IN-CFC-Suntikan Modal'!E12 -> 0 | E15: ='IN-CFC-Suntikan Modal'!F12 -> 0 | F15: ='IN-CFC-Suntikan Modal'!G12 -> 0 | G15: ='IN-CFC-Suntikan Modal'!H12 -> 0 | H15: ='IN-CFC-Suntikan Modal'!I12 -> 0 | I15: ='IN-CFC-Suntikan Modal'!J12 -> 0 | J15: ='IN-CFC-Suntikan Modal'!K12 -> 0 | ... R15: ='IN-CFC-Suntikan Modal'!S12 -> 0 | S15: =SUM(C15:R15) -> 0
A16: TOTAL PENERIMAAN KAS | C16: =SUM(C13:C15) -> 0 | D16: =SUM(D13:D15) -> 0 | E16: =SUM(E13:E15) -> 0 | F16: =SUM(F13:F15) -> 838451777 | G16: =SUM(G13:G15) -> 120390000 | H16: =SUM(H13:H15) -> 291003015 | I16: =SUM(I13:I15) -> 5134305 | J16: =SUM(J13:J15) -> 885839057 | ... S16: =SUM(S13:S15) -> 7133738712
A18: PENGELUARAN | S18: =SUM(B18:B18:S18) -> 0
A19: Pajak | B19: ACC | C19: ='OUT-ACC-PAJAK'!D35 -> 0 | D19: ='OUT-ACC-PAJAK'!E35 -> 0 | E19: ='OUT-ACC-PAJAK'!F35 -> 0 | F19: ='OUT-ACC-PAJAK'!G35 -> 0 | G19: ='OUT-ACC-PAJAK'!H35 -> 46190827 | H19: ='OUT-ACC-PAJAK'!I35 -> 0 | I19: ='OUT-ACC-PAJAK'!J35 -> 104638748 | J19: ='OUT-ACC-PAJAK'!K35 -> 0 | ... R19: ='OUT-ACC-PAJAK'!S35 -> 0 | S19: =SUM(C19:R19) -> 3.8858056e+08
A20: Gaji & Benefit Karyawan | B20: HR | C20: ='OUT - HR - Gaji & Benefit'!D18 -> 0 | D20: ='OUT - HR - Gaji & Benefit'!E18 -> 0 | E20: ='OUT - HR - Gaji & Benefit'!F18 -> 0 | F20: ='OUT - HR - Gaji & Benefit'!G18 -> 0 | G20: ='OUT - HR - Gaji & Benefit'!H18 -> 0 | H20: ='OUT - HR - Gaji & Benefit'!I18 -> 0 | I20: ='OUT - HR - Gaji & Benefit'!J18 -> 0 | J20: ='OUT - HR - Gaji & Benefit'!K18 -> 0 | ... R20: ='OUT - HR - Gaji & Benefit'!S18 -> 250000000 | S20: =SUM(C20:R20) -> 250000000
A21: Corporate Expenses | B21: CFC | C21: ='OUT - CFC - Corporate Expenses'!H33 -> 0 | D21: ='OUT - CFC - Corporate Expenses'!I33 -> 0 | E21: ='OUT - CFC - Corporate Expenses'!J33 -> 0 | F21: ='OUT - CFC - Corporate Expenses'!K33 -> 0 | G21: ='OUT - CFC - Corporate Expenses'!L33 -> 81607500 | H21: ='OUT - CFC - Corporate Expenses'!M33 -> 74636000 | I21: ='OUT - CFC - Corporate Expenses'!N33 -> 101691071 | J21: ='OUT - CFC - Corporate Expenses'!O33 -> 0 | ... R21: ='OUT - CFC - Corporate Expenses'!W33 -> 35000000 | S21: =SUM(C21:R21) -> 300375769
A22: Operational Kantor (ACC) | B22: ACC | C22: ='OUT - ACC - Ops Kantor'!D21 -> 0 | D22: ='OUT - ACC - Ops Kantor'!E21 -> 0 | E22: ='OUT - ACC - Ops Kantor'!F21 -> 0 | F22: ='OUT - ACC - Ops Kantor'!G21 -> 0 | G22: ='OUT - ACC - Ops Kantor'!H21 -> 0 | H22: ='OUT - ACC - Ops Kantor'!I21 -> 0 | I22: ='OUT - ACC - Ops Kantor'!J21 -> 0 | J22: ='OUT - ACC - Ops Kantor'!K21 -> 0 | ... R22: ='OUT - ACC - Ops Kantor'!S21 -> 0 | S22: =SUM(C22:R22) -> 0
A23: Operational Kantor (ACS) | B23: ACS | C23: ='OUT-ACS-OPS'!D18 -> 0 | D23: ='OUT-ACS-OPS'!E18 -> 0 | E23: ='OUT-ACS-OPS'!F18 -> 0 | F23: ='OUT-ACS-OPS'!G18 -> 0 | G23: ='OUT-ACS-OPS'!H18 -> 0 | H23: ='OUT-ACS-OPS'!I18 -> 0 | I23: ='OUT-ACS-OPS'!J18 -> 0 | J23: ='OUT-ACS-OPS'!K18 -> 0 | ... R23: ='OUT-ACS-OPS'!S18 -> 0 | S23: =SUM(C23:R23) -> 0
A24: Operational Kantor (BAS) | B24: BAS | C24: ='OUT-BAS-OPS'!D18 -> 0 | D24: ='OUT-BAS-OPS'!E18 -> 0 | E24: ='OUT-BAS-OPS'!F18 -> 0 | F24: ='OUT-BAS-OPS'!G18 -> 0 | G24: ='OUT-BAS-OPS'!H18 -> 0 | H24: ='OUT-BAS-OPS'!I18 -> 0 | I24: ='OUT-BAS-OPS'!J18 -> 0 | J24: ='OUT-BAS-OPS'!K18 -> 0 | ... R24: ='OUT-BAS-OPS'!S18 -> 0 | S24: =SUM(C24:R24) -> 0
A25: Operational Kantor (BID) | B25: BID | C25: ='OUT-BID-OPS'!D12 -> 0 | D25: ='OUT-BID-OPS'!E12 -> 0 | E25: ='OUT-BID-OPS'!F12 -> 0 | F25: ='OUT-BID-OPS'!G12 -> 0 | G25: ='OUT-BID-OPS'!H12 -> 0 | H25: ='OUT-BID-OPS'!I12 -> 0 | I25: ='OUT-BID-OPS'!J12 -> 0 | J25: ='OUT-BID-OPS'!K12 -> 0 | ... R25: ='OUT-BID-OPS'!S12 -> 0 | S25: =SUM(C25:R25) -> 0
A26: Operational Kantor (CFC) | B26: CFC | C26: ='OUT-CFC-OPS'!D12 -> 0 | D26: ='OUT-CFC-OPS'!E12 -> 0 | E26: ='OUT-CFC-OPS'!F12 -> 0 | F26: ='OUT-CFC-OPS'!G12 -> 0 | G26: ='OUT-CFC-OPS'!H12 -> 0 | H26: ='OUT-CFC-OPS'!I12 -> 0 | I26: ='OUT-CFC-OPS'!J12 -> 0 | J26: ='OUT-CFC-OPS'!K12 -> 0 | ... R26: ='OUT-CFC-OPS'!S12 -> 0 | S26: =SUM(C26:R26) -> 0
A27: Operational Kantor (GA) | B27: GA | C27: ='OUT-GA-OPS'!D26 -> 0 | D27: ='OUT-GA-OPS'!E26 -> 0 | E27: ='OUT-GA-OPS'!F26 -> 0 | F27: ='OUT-GA-OPS'!G26 -> 0 | G27: ='OUT-GA-OPS'!H26 -> 7900000 | H27: ='OUT-GA-OPS'!I26 -> 0 | I27: ='OUT-GA-OPS'!J26 -> 300000 | J27: ='OUT-GA-OPS'!K26 -> 0 | ... R27: ='OUT-GA-OPS'!S26 -> 0 | S27: =SUM(C27:R27) -> 26540000
A28: Operational Kantor (HR) | B28: HR | C28: ='OUT-HR-OPS'!D15 -> 0 | D28: ='OUT-HR-OPS'!E15 -> 0 | E28: ='OUT-HR-OPS'!F15 -> 0 | F28: ='OUT-HR-OPS'!G15 -> 0 | G28: ='OUT-HR-OPS'!H15 -> 0 | H28: ='OUT-HR-OPS'!I15 -> 0 | I28: ='OUT-HR-OPS'!J15 -> 2000000 | J28: ='OUT-HR-OPS'!K15 -> 2000000 | ... R28: ='OUT-HR-OPS'!S15 -> 0 | S28: =SUM(C28:R28) -> 16500000
A29: Operational Kantor (PD) | B29: PD | C29: ='OUT-PD-OPS'!D12 -> 0 | D29: ='OUT-PD-OPS'!E12 -> 0 | E29: ='OUT-PD-OPS'!F12 -> 0 | F29: ='OUT-PD-OPS'!G12 -> 0 | G29: ='OUT-PD-OPS'!H12 -> 0 | H29: ='OUT-PD-OPS'!I12 -> 0 | I29: ='OUT-PD-OPS'!J12 -> 0 | J29: ='OUT-PD-OPS'!K12 -> 0 | ... R29: ='OUT-PD-OPS'!S12 -> 0 | S29: =SUM(C29:R29) -> 0
A30: Operational Kantor (SS) | B30: SS | C30: ='OUT-SS-OPS'!D12 -> 0 | D30: ='OUT-SS-OPS'!E12 -> 0 | E30: ='OUT-SS-OPS'!F12 -> 0 | F30: ='OUT-SS-OPS'!G12 -> 0 | G30: ='OUT-SS-OPS'!H12 -> 0 | H30: ='OUT-SS-OPS'!I12 -> 0 | I30: ='OUT-SS-OPS'!J12 -> 0 | J30: ='OUT-SS-OPS'!K12 -> 0 | ... R30: ='OUT-SS-OPS'!S12 -> 0 | S30: =SUM(C30:R30) -> 0
A31: Operational Kantor (SO) | B31: SO | C31: ='OUT-SO-OPS'!D12 -> 0 | D31: ='OUT-SO-OPS'!E12 -> 0 | E31: ='OUT-SO-OPS'!F12 -> 0 | F31: ='OUT-SO-OPS'!G12 -> 0 | G31: ='OUT-SO-OPS'!H12 -> 0 | H31: ='OUT-SO-OPS'!I12 -> 0 | I31: ='OUT-SO-OPS'!J12 -> 0 | J31: ='OUT-SO-OPS'!K12 -> 0 | ... R31: ='OUT-SO-OPS'!S12 -> 0 | S31: =SUM(C31:R31) -> 0
A32: Operational Kantor (TEP) | B32: TEP | C32: ='OUT-TEP-OPS'!D12 -> 0 | D32: ='OUT-TEP-OPS'!E12 -> 0 | E32: ='OUT-TEP-OPS'!F12 -> 0 | F32: ='OUT-TEP-OPS'!G12 -> 0 | G32: ='OUT-TEP-OPS'!H12 -> 0 | H32: ='OUT-TEP-OPS'!I12 -> 0 | I32: ='OUT-TEP-OPS'!J12 -> 0 | J32: ='OUT-TEP-OPS'!K12 -> 0 | ... R32: ='OUT-TEP-OPS'!S12 -> 0 | S32: =SUM(C32:R32) -> 0
A33: Operational Kantor (RESERVASI) | B33: RESERVASI | C33: ='OUT-RESERVASI-OPS'!D12 -> 0 | D33: ='OUT-RESERVASI-OPS'!E12 -> 0 | E33: ='OUT-RESERVASI-OPS'!F12 -> 0 | F33: ='OUT-RESERVASI-OPS'!G12 -> 0 | G33: ='OUT-RESERVASI-OPS'!H12 -> 0 | H33: ='OUT-RESERVASI-OPS'!I12 -> 0 | I33: ='OUT-RESERVASI-OPS'!J12 -> 0 | J33: ='OUT-RESERVASI-OPS'!K12 -> 0 | ... R33: ='OUT-RESERVASI-OPS'!S12 -> 0 | S33: =SUM(C33:R33) -> 0
A34: Operational Kantor (TAKSHAKA) | B34: TAKSHAKA | C34: ='OUT-TAKSHAKA-OPS'!D12 -> 0 | D34: ='OUT-TAKSHAKA-OPS'!E12 -> 0 | E34: ='OUT-TAKSHAKA-OPS'!F12 -> 0 | F34: ='OUT-TAKSHAKA-OPS'!G12 -> 0 | G34: ='OUT-TAKSHAKA-OPS'!H12 -> 0 | H34: ='OUT-TAKSHAKA-OPS'!I12 -> 0 | I34: ='OUT-TAKSHAKA-OPS'!J12 -> 0 | J34: ='OUT-TAKSHAKA-OPS'!K12 -> 0 | ... R34: ='OUT-TAKSHAKA-OPS'!S12 -> 0 | S34: =SUM(C34:R34) -> 0
A35: Bunga & Angsuran | B35: CFC | C35: ='OUT - CFC - Bunga & Angsuran'!I15 -> 0 | D35: ='OUT - CFC - Bunga & Angsuran'!J15 -> 0 | E35: ='OUT - CFC - Bunga & Angsuran'!K15 -> 0 | F35: ='OUT - CFC - Bunga & Angsuran'!L15 -> 0 | G35: ='OUT - CFC - Bunga & Angsuran'!M15 -> 0 | H35: ='OUT - CFC - Bunga & Angsuran'!N15 -> 0 | I35: ='OUT - CFC - Bunga & Angsuran'!O15 -> 0 | J35: ='OUT - CFC - Bunga & Angsuran'!P15 -> 0 | ... R35: ='OUT - CFC - Bunga & Angsuran'!X15 -> 0 | S35: =SUM(C35:R35) -> 0
A36: Cost Of Revenue | B36: TEP | C36: ='OUT - TEP - Cost Of Revenue'!H27 -> 8.9106224e+08 | D36: ='OUT - TEP - Cost Of Revenue'!I27 -> 0 | E36: ='OUT - TEP - Cost Of Revenue'!J27 -> 0 | F36: ='OUT - TEP - Cost Of Revenue'!K27 -> 0 | G36: ='OUT - TEP - Cost Of Revenue'!L27 -> 276735094 | H36: ='OUT - TEP - Cost Of Revenue'!M27 -> 0 | I36: ='OUT - TEP - Cost Of Revenue'!N27 -> 2.9284306e+08 | J36: ='OUT - TEP - Cost Of Revenue'!O27 -> 0 | ... R36: ='OUT - TEP - Cost Of Revenue'!W27 -> 0 | S36: =SUM(C36:R36) -> 1.5792729e+09
A37: Hutang Usaha | B37: CFC | C37: ='OUT - CFC - Hutang Usaha'!H103 -> 0 | D37: ='OUT - CFC - Hutang Usaha'!I103 -> 0 | E37: ='OUT - CFC - Hutang Usaha'!J103 -> 0 | F37: ='OUT - CFC - Hutang Usaha'!K103 -> 18650000 | G37: ='OUT - CFC - Hutang Usaha'!L103 -> 1014560576 | H37: ='OUT - CFC - Hutang Usaha'!M103 -> 0 | I37: ='OUT - CFC - Hutang Usaha'!N103 -> 203483000 | J37: ='OUT - CFC - Hutang Usaha'!O103 -> 0 | ... R37: ='OUT - CFC - Hutang Usaha'!W103 -> 0 | S37: =SUM(C37:R37) -> 1763734063
A38: Pemberian Pinjaman | B38: HR | C38: ='OUT - HR - Pemberian Pinjaman'!D12 -> 0 | D38: ='OUT - HR - Pemberian Pinjaman'!E12 -> 0 | E38: ='OUT - HR - Pemberian Pinjaman'!F12 -> 0 | F38: ='OUT - HR - Pemberian Pinjaman'!G12 -> 0 | G38: ='OUT - HR - Pemberian Pinjaman'!H12 -> 0 | H38: ='OUT - HR - Pemberian Pinjaman'!I12 -> 0 | I38: ='OUT - HR - Pemberian Pinjaman'!J12 -> 0 | J38: ='OUT - HR - Pemberian Pinjaman'!K12 -> 0 | ... R38: ='OUT - HR - Pemberian Pinjaman'!S12 -> 0 | S38: =SUM(C38:R38) -> 0
A39: Sales Call | B39: TEP | C39: ='OUT - TEP - Sales Call'!D12 -> 0 | D39: ='OUT - TEP - Sales Call'!E12 -> 0 | E39: ='OUT - TEP - Sales Call'!F12 -> 0 | F39: ='OUT - TEP - Sales Call'!G12 -> 0 | G39: ='OUT - TEP - Sales Call'!H12 -> 0 | H39: ='OUT - TEP - Sales Call'!I12 -> 0 | I39: ='OUT - TEP - Sales Call'!J12 -> 0 | J39: ='OUT - TEP - Sales Call'!K12 -> 0 | ... R39: ='OUT - TEP - Sales Call'!S12 -> 0 | S39: =SUM(C39:R39) -> 0
A40: Pengembalian Suntikan Modal dari Owner | B40: CFC | C40: ='OUT-CFC -Pengem Sunti Modal Own'!D12 -> 0 | D40: ='OUT-CFC -Pengem Sunti Modal Own'!E12 -> 0 | E40: ='OUT-CFC -Pengem Sunti Modal Own'!F12 -> 0 | F40: ='OUT-CFC -Pengem Sunti Modal Own'!G12 -> 0 | G40: ='OUT-CFC -Pengem Sunti Modal Own'!H12 -> 0 | H40: ='OUT-CFC -Pengem Sunti Modal Own'!I12 -> 0 | I40: ='OUT-CFC -Pengem Sunti Modal Own'!J12 -> 0 | J40: ='OUT-CFC -Pengem Sunti Modal Own'!K12 -> 0 | ... R40: ='OUT-CFC -Pengem Sunti Modal Own'!S12 -> 0 | S40: =SUM(C40:R40) -> 0
S41: =SUM(C41:R41) -> 0
A42: TOTAL PENGELUARAN KAS | C42: =SUM(C19:C40) -> 8.9106224e+08 | D42: =SUM(D19:D40) -> 0 | E42: =SUM(E19:E40) -> 0 | F42: =SUM(F19:F40) -> 18650000 | G42: =SUM(G19:G40) -> 1.426994e+09 | H42: =SUM(H19:H40) -> 74636000 | I42: =SUM(I19:I40) -> 7.0495588e+08 | J42: =SUM(J19:J40) -> 2000000 | ... R42: =SUM(R19:R40) -> 285000000 | S42: =SUM(S19:S41) -> 4.3250033e+09
S43: =SUM(C43:R43) -> 0
A44: Pengembalian Pinjaman Pokok Modal | S44: =SUM(C44:R44) -> 0
A45: Pembelanjaan Modal (Capital Expenditures) | S45: =SUM(C45:R45) -> 0
...

Sheet IN-ACC-Piutang & Revenue
F1: Hari Kerja
F2: Jadwal Pembayaran (Selasa/ Jumat)
F3: Hari Libur
E4: Pengeluaran Biaya Operating Sales & Marketing | F4: 22 Okt 2021
E5: JUMAT | F5: SABTU | G5: MINGGU | H5: SENIN | I5: SELASA | J5: RABU | K5: KAMIS | L5: JUMAT | M5: SABTU | N5: MINGGU | O5: SENIN | P5: SELASA | Q5: RABU | R5: KAMIS | S5: JUMAT | T5: SABTU
B6: DESKRIPSI | C6: NOMINAL | D6: TANGGAL | E6: 45947 | F6: 45948 | G6: 45949 | H6: 45950 | I6: 45951 | J6: 45952 | K6: 45953 | L6: 45954 | M6: 45955 | N6: 45956 | O6: 45957 | P6: 45958 | Q6: 45959 | R6: 45960 | S6: 45961 | T6: 45962 | U6: TOTAL
B7: World Bank VP DFI Site Visitation tgl 22-23 Aug 2025 | C7: 115426850 | S7: 115426850 | U7: =SUM(E7:T7) -> 115426850
B8: WNS BALI - Forest Therapy Kemenpar Soulful Escape: Recharge & Rediscover 8D7N Bali Yogyakarta Famtrip New Zealand tgl 25 Aug 2025 | C8: 20000000 | H8: 20000000 | U8: =SUM(E8:T8) -> 20000000
B9: UOB INDONESIA - UOB Brand Internal Campaign Service May - September 2025 | C9: 144437585 | J9: 50000000 | T9: 144437585 | U9: =SUM(E9:T9) -> 194437585
B10: UOB INDONESIA - Transport Arrangement Mr. Hendra UOB Indonesia tgl 22-23 Aug 2025 | C10: 8325000 | T10: 8325000 | U10: =SUM(E10:T10) -> 8325000
B11: PROTELINDO GROUP - Corporate Travel Protelindo Group tgl 1-30 August 2025 | C11: 45500363 | S11: 45500363 | U11: =SUM(E11:T11) -> 45500363
B12: UOB INDONESIA - UOB BOD Board Retreat tgl 2-6 September 2025 | C12: 850267131 | T12: 850267131 | U12: =SUM(E12:T12) -> 850267131
B13: PT ROCHE INDONESIA - Booth Roche at Pertemuan Ilmiah Tahunan Perhimpunan Dokter Spesial Patologi Anatomik in Yogyakarta on September 5-7, 2025 | C13: 87198216 | L13: 87198216 | U13: =SUM(E13:T13) -> 87198216
B14: UN WOMEN INDONESIA - 25th Anniversary of UNSCR 1325 Celebration : Exhibition, Workshop, and Launch of the Indonesian CSO Network for 17-19 September 2025 | C14: 574887500 | S14: 574887500 | U14: =SUM(E14:T14) -> 574887500
B15: WORLD BANK - World Bank VP for East Asia and Pacific Region Visit to Jakarta Tour tgl 20 Sep 2025 | C15: 95825400 | S15: 95825400 | U15: =SUM(E15:T15) -> 95825400
B16: PT FINACCEL TEKNOLOGI INDONESIA - Tour Company Outing Team 2025 in Bogor on September 26-27, 2025 (Term 2) | C16: 77025563 | O16: 77025563 | U16: =SUM(E16:T16) -> 77025563
B17: RS SILOAM MRCC SEMANGGI - Backdrop Arrangement - Hardoknas tgl 1-31 Oktober 2025 (Term 1) | C17: 5134305 | K17: 5134305 | U17: =SUM(E17:T17) -> 5134305
B18: RS SILOAM MRCC SEMANGGI - Backdrop Arrangement - Hardoknas tgl 1-31 Oktober 2025 (Term 2) | C18: 5134305 | T18: 5134305 | U18: =SUM(E18:T18) -> 5134305
B19: PT DONALDSON FILTRATION INDONESIA - Halfday Tour Sightseeing in Bandung on November 11, 2025 | C19: 138845685 | T19: 138845685 | U19: =SUM(E19:T19) -> 138845685
B20: PT DONALDSON FILTRATION INDONESIA - Halfday Tour Sightseeing in Bandung on November 11, 2025 (Additional Term 1) | C20: 36324750 | T20: 36324750 | U20: =SUM(E20:T20) -> 36324750
B21: PT DONALDSON FILTRATION INDONESIA - Halfday Tour Sightseeing in Bandung on November 11, 2025 (Additional Term 2) | C21: 15567750 | T21: 15567750 | U21: =SUM(E21:T21) -> 15567750
B22: ILO INDONESIA - ILO - Official Visit of Federal Councilor of Switzerland to KPBS Pangalengan on October 2, 2025 | C22: 191003015 | J22: 191003015 | U22: =SUM(E22:T22) -> 191003015
B23: PT BADAN ESSENCE INDONESIA - IFF Festive Night 2025 (Additional) | C23: 109890000 | I23: 109890000 | U23: =SUM(E23:T23) -> 109890000
B24: TEAM INTERNATIONAL TEXTILE MANUFACTURER FEDERATION - ITMF Annual Conference & IAF World Fashion Convention in Yogyakarta on October 24-26, 2025 (Term 3) | C24: 155058600 | T24: 155058600 | U24: =SUM(E24:T24) -> 155058600
B25: ASOSIASI PERTEKSTILAN INDONESIA (API) - Booth Diamond APR - ITMF Annual Conference & IAF World Fashion Convention in Yogyakarta on October 24, 2025 | C25: 54945000 | T25: 54945000 | U25: =SUM(E25:T25) -> 54945000
B26: APDMET - Sosialisasi Hasil Munas V dan Rapat Kerja ADPMET 2025 in Cepu on October 15, 2025 (Term 2) | C26: 19658000 | P26: 19658000 | U26: =SUM(E26:T26) -> 19658000
B27: JOE - Sosialisasi Hasil Munas V dan Rapat Kerja ADPMET 2025 in Cepu on October 15, 2025 (Term 3 / Dana Sponsorship) | C27: 50000000 | J27: 50000000 | U27: =SUM(E27:T27) -> 50000000
B28: PT KROM BANK INDONESIA TBK - Tour Annual Gathering tgl 24-25 Oktober 2025 (Term 1) | C28: 411443637 | H28: 411443637 | U28: =SUM(E28:T28) -> 411443637
B29: PT KROM BANK INDONESIA TBK - Tour Annual Gathering tgl 24-25 Oktober 2025 (Term 2) | C29: 617165456 | U29: =SUM(E29:T29) -> 0
B30: RANTAI TEKSTIL LESTARI - Meeting RTL tgl 23 October 2025 (Term 2) | C30: =189560250-151648200 -> 37912050 | U30: =SUM(E30:T30) -> 0
B31: PT WNS - BI KPW Sulawesi Utara Mastering Smart Correspondence with AI | C31: 7000000 | T31: 7000000 | U31: =SUM(E31:T31) -> 7000000
B32: KEMENPAR - Workshop Kejutan tgl 1-2 Oktober 2025 (WNS) | C32: 199050000 | L32: 199050000 | U32: =SUM(E32:T32) -> 199050000
B33: KEMENPAR - Workshop Kejutan tgl 1-2 Oktober 2025 (YPN) | C33: 49950000 | L33: 49950000 | U33: =SUM(E33:T33) -> 49950000
B34: KEMENPAR - Workshop Kejutan tgl 1-2 Oktober 2025 (Kwitansi WNS) | C34: 990000 | L34: 990000 | U34: =SUM(E34:T34) -> 990000
B35: PT RINTIS SEJAHTERA - PRIMA Executive Gathering 2025 | C35: 442500000 | T35: 442500000 | U35: =SUM(E35:T35) -> 442500000
B36: PT DATA SINERGITAMA JAYA TBK - Elitery Company Gathering Team Building & Gala Dinner (Term 1) | C36: 407008140 | H36: 407008140 | U36: =SUM(E36:T36) -> 407008140
B37: PT DATA SINERGITAMA JAYA TBK - Elitery Company Gathering Team Building & Gala Dinner (Term 2) | C37: 174432060 | T37: 174432060 | U37: =SUM(E37:T37) -> 174432060
B38: GIZ INDONESIA - Green Infrastructur Initiative World Clean Up Day Event in Batu Lumbang Mangrove Bali on October 13, 2025 | C38: 276975000 | S38: 276975000 | U38: =SUM(E38:T38) -> 276975000
B39: BI KPW SULUT - Transportation Arrival (MRP) | C39: 133235178 | L39: 133235178 | U39: =SUM(E39:T39) -> 133235178
B40: BI KPW SULUT - Transportation Departure (MRP) | C40: 110562488 | L40: 110562488 | U40: =SUM(E40:T40) -> 110562488
...

Sheet IN-CFC-Penerimaan PengemPinj
B1: Kategori : | C1: Cash Outflow (Penerimaan Kas) | E1: Hari Kerja
B2: Pos Akun : | C2: Pemberian Pinjaman | E2: Jadwal Pembayaran (Selasa/ Jumat)
B3: Periode : | E3: Hari Libur
B4: Updated on : | C4: ='CF Realisasi new'!B8 -> 45947 | D4: Pengeluaran Biaya Operating Sales & Marketing | E4: Pengeluaran Biaya Operating Sales & Marketing
D5: JUMAT | E5: SABTU | F5: MINGGU | G5: SENIN | H5: SELASA | I5: RABU | J5: KAMIS | K5: JUMAT | L5: SABTU | M5: MINGGU | N5: SENIN | O5: SELASA | P5: RABU | Q5: KAMIS | R5: JUMAT | S5: SABTU
A6: PENERIMAAN PINJAMAN | B6: NOMINAL | C6: TANGGAL | D6: 45947 | E6: 45948 | F6: 45949 | G6: 45950 | H6: 45951 | I6: 45952 | J6: 45953 | K6: 45954 | L6: 45955 | M6: 45956 | N6: 45957 | O6: 45958 | P6: 45959 | Q6: 45960 | R6: 45961 | S6: 45962 | T6: TOTAL
T7: =SUM(D7:S7) -> 0
T8: =SUM(D8:S8) -> 0
T9: =SUM(D9:S9) -> 0
T10: =SUM(D10:S10) -> 0
T11: =SUM(D11:S11) -> 0
T12: =SUM(D12:S12) -> 0
T13: =SUM(D13:S13) -> 0
T14: =SUM(D14:S14) -> 0
T15: =SUM(D15:S15) -> 0
T16: =SUM(D16:S16) -> 0
T17: =SUM(D17:S17) -> 0
T18: =SUM(D18:S18) -> 0
B19: TOTAL PEMBERIAN PINJAMAN | D19: =SUM(D7:D18) -> 0 | E19: =SUM(E7:E18) -> 0 | F19: =SUM(F7:F18) -> 0 | G19: =SUM(G7:G18) -> 0 | H19: =SUM(H7:H18) -> 0 | I19: =SUM(I7:I18) -> 0 | J19: =SUM(J7:J18) -> 0 | K19: =SUM(K7:K18) -> 0 | ... T19: =SUM(T7:T18) -> 0

Sheet IN-CFC-Suntikan Modal
B1: Kategori : | C1: Cash Outflow (Penerimaan Kas) | F1: Hari Kerja
B2: Pos Akun : | C2: IN-Suntikan Modal | F2: Jadwal Pembayaran (Selasa/ Jumat)
B3: Periode : | F3: Hari Libur
B4: Updated on : | C4: ='CF Realisasi new'!B8 -> 45947 | D4: Pengeluaran Biaya Operating Sales & Marketing
D5: JUMAT | E5: SABTU | F5: MINGGU | G5: SENIN | H5: SELASA | I5: RABU | J5: KAMIS | K5: JUMAT | L5: SABTU | M5: MINGGU | N5: SENIN | O5: SELASA | P5: RABU | Q5: KAMIS | R5: JUMAT | S5: SABTU
A6: DESKRIPSI | B6: NOMINAL | C6: TANGGAL | D6: 45947 | E6: 45948 | F6: 45949 | G6: 45950 | H6: 45951 | I6: 45952 | J6: 45953 | K6: 45954 | L6: 45955 | M6: 45956 | N6: 45957 | O6: 45958 | P6: 45959 | Q6: 45960 | R6: 45961 | S6: 45962 | T6: TOTAL
T7: =SUM(D7:S7) -> 0
B8: Menerima suntikan modal | T8: =SUM(D8:S8) -> 0
T9: =SUM(D9:S9) -> 0
T10: =SUM(D10:S10) -> 0
T11: =SUM(D11:S11) -> 0
B12: TOTAL PENERIMAAN SUNTIKAN MODAL DARI OWNER | D12: =SUM(D7:D11) -> 0 | E12: =SUM(E7:E11) -> 0 | F12: =SUM(F7:F11) -> 0 | G12: =SUM(G7:G11) -> 0 | H12: =SUM(H7:H11) -> 0 | I12: =SUM(I7:I11) -> 0 | J12: =SUM(J7:J11) -> 0 | K12: =SUM(K7:K11) -> 0 | ... T12: =SUM(T7:T11) -> 0

Sheet OUT-ACC-PAJAK
B1: Kategori : | C1: Cash Outflow (Pengeluaran Kas)
B2: Pos Akun : | C2: OUT-ACC-Pajak
B3: Periode :
B4: Updated on : | C4: ='CF Realisasi new'!B8 -> 45947 | D4: Pengeluaran Biaya Operating Sales & Marketing
D5: JUMAT | E5: SABTU | F5: MINGGU | G5: SENIN | H5: SELASA | I5: RABU | J5: KAMIS | K5: JUMAT | L5: SABTU | M5: MINGGU | N5: SENIN | O5: SELASA | P5: RABU | Q5: KAMIS | R5: JUMAT | S5: SABTU
A6: DESKRIPSI | B6: NOMINAL | C6: TANGGAL | D6: 45947 | E6: 45948 | F6: 45949 | G6: 45950 | H6: 45951 | I6: 45952 | J6: 45953 | K6: 45954 | L6: 45955 | M6: 45956 | N6: 45957 | O6: 45958 | P6: 45959 | Q6: 45960 | R6: 45961 | S6: 45962 | T6: TOTAL
A7: PPN MEI 2025 | B7: 104638748 | J7: 104638748 | T7: =SUM(D7:S7) -> 104638748
A8: PPH 23, 26, 4(2) JUNI | B8: 12025717 | O8: 12025717 | T8: =SUM(D8:S8) -> 12025717
A9: PPN IMPOR JUNI | B9: 109222 | H9: 109222 | T9: =SUM(D9:S9) -> 109222
A10: PPN JUNI 2025 | B10: 216881482 | Q10: 216881482 | T10: =SUM(D10:S10) -> 216881482
A11: PPH 23 & 26 JULI 2025 | B11: 8843790 | O11: 8843790 | T11: =SUM(D11:S11) -> 8843790
A12: PPN IMPOR JULI | B12: 93952 | H12: 93952 | T12: =SUM(D12:S12) -> 93952
A13: SKPKB PPN DES ANG 10 | B13: 6311430 | H13: 6311430 | T13: =SUM(D13:S13) -> 6311430
A14: PPN JULI 2025 | B14: 0 | T14: =SUM(D14:S14) -> 0
A15: SKPKB PPN SEPTEMBER ANG 17 | H15: 1511359.5 | T15: =SUM(D15:S15) -> 1511359.5
A16: SKPKB PPN AGUSTUS ANG 17 | H16: 4159986.9 | T16: =SUM(D16:S16) -> 4159986.9
A17: SKPKB PPN NOVEMBER ANG 17 | H17: 4326280.6 | T17: =SUM(D17:S17) -> 4326280.6
A18: SKPKB PPN OKTOBER ANG 17 | H18: 9861633.8 | T18: =SUM(D18:S18) -> 9861633.8
A19: SKPKB PPN DESEMBER ANG 17 | H19: 6311430.1 | T19: =SUM(D19:S19) -> 6311430.1
A20: SKPKB PPN JULI ANG 17 | H20: 34696.833 | T20: =SUM(D20:S20) -> 34696.833
A21: SKPKB PPH 23 MARET ANG 17 | H21: 532953.92 | T21: =SUM(D21:S21) -> 532953.92
A22: SKPKB PPH 23 APRIL ANG 17 | H22: 164520.21 | T22: =SUM(D22:S22) -> 164520.21
A23: SKPKB PPH 23 MEI ANG 17 | H23: 435969.92 | T23: =SUM(D23:S23) -> 435969.92
A24: SKPKB PPH 23 JUNI ANG 17 | H24: 306404.21 | T24: =SUM(D24:S24) -> 306404.21
A25: SKPKB PPH 23 JULI ANG 17 | H25: 306404.21 | T25: =SUM(D25:S25) -> 306404.21
A26: SKPKB PPH 23 AGUSTUS ANG 17 | H26: 301269.92 | T26: =SUM(D26:S26) -> 301269.92
... A32: SKPKB STP PPN ANG 17 | H32: 1436205.4 | T32: =SUM(D32:S32) -> 1436205.4
T34: =SUM(D34:S34) -> 0
B35: TOTAL PAJAK | D35: =SUM(D7:D34) -> 0 | E35: =SUM(E7:E34) -> 0 | F35: =SUM(F7:F34) -> 0 | G35: =SUM(G7:G34) -> 0 | H35: =SUM(H7:H34) -> 46190827 | I35: =SUM(I7:I34) -> 0 | J35: =SUM(J7:J34) -> 104638748 | K35: =SUM(K7:K34) -> 0 | ... S35: =SUM(S7:S34) -> 0 | T35: =SUM(T7:T33) -> 3.8858056e+08

Sheet OUT - HR - Gaji & Benefit
B1: Kategori : | C1: Cash Outflow (Pengeluaran Kas) | E1: Hari Kerja
B2: Pos Akun : | C2: Out-HR- Gaji & Benefit | E2: Jadwal Pembayaran (Selasa/ Jumat)
B3: Periode : | E3: Hari Libur
B4: Updated on : | C4: ='OUT-ACC-PAJAK'!C4 -> 45947 | D4: Pengeluaran Biaya Operating Sales & Marketing | E4: Pengeluaran Biaya Operating Sales & Marketing
D5: JUMAT | E5: SABTU | F5: MINGGU | G5: SENIN | H5: SELASA | I5: RABU | J5: KAMIS | K5: JUMAT | L5: SABTU | M5: MINGGU | N5: SENIN | O5: SELASA | P5: RABU | Q5: KAMIS | R5: JUMAT | S5: SABTU
A6: KETERANGAN | B6: NOMINAL | C6: TANGGAL | D6: 45947 | E6: 45948 | F6: 45949 | G6: 45950 | H6: 45951 | I6: 45952 | J6: 45953 | K6: 45954 | L6: 45955 | M6: 45956 | N6: 45957 | O6: 45958 | P6: 45959 | Q6: 45960 | R6: 45961 | S6: 45962 | T6: TOTAL
S7: 250000000 | T7: =SUM(D7:S7) -> 250000000
T8: =SUM(D8:S8) -> 0
T9: =SUM(D9:S9) -> 0
T10: =SUM(D10:S10) -> 0
T11: =SUM(D11:S11) -> 0
T12: =SUM(D12:S12) -> 0
T13: =SUM(D13:S13) -> 0
T14: =SUM(D14:S14) -> 0
T15: =SUM(D15:S15) -> 0
T16: =SUM(D16:S16) -> 0
T17: =SUM(D17:S17) -> 0
B18: TOTAL BIAYA HRD | D18: =SUM(D7:D17) -> 0 | E18: =SUM(E7:E17) -> 0 | F18: =SUM(F7:F17) -> 0 | G18: =SUM(G7:G17) -> 0 | H18: =SUM(H7:H17) -> 0 | I18: =SUM(I7:I17) -> 0 | J18: =SUM(J7:J17) -> 0 | K18: =SUM(K7:K17) -> 0 | ... T18: =SUM(T7:T17) -> 250000000

Sheet OUT - CFC - Corporate Expenses
C1: Kategori : | E1: Cash Outflow (Pengeluaran Kas) | J1: Hari Kerja
C2: Pos Akun : | E2: Out-CFC-Corporate Expenses | J2: Jadwal Pembayaran (Selasa/ Jumat)
C3: Periode : | J3: Hari Libur
C4: Updated on : | E4: 45947 | I4: Pengeluaran Biaya Operating Sales & Marketing | J4: Pengeluaran Biaya Operating Sales & Marketing
H5: JUMAT | I5: SABTU | J5: MINGGU | K5: SENIN | L5: SELASA | M5: RABU | N5: KAMIS | O5: JUMAT | P5: SABTU | Q5: MINGGU | R5: SENIN | S5: SELASA | T5: RABU | U5: KAMIS | V5: JUMAT | W5: SABTU
A6: A | B6: cicilan/bln | C6: KETERANGAN | E6: NOMINAL | F6: TGL JATUH TEMPO | G6: TANGGAL | H6: 45947 | I6: 45948 | J6: 45949 | K6: 45950 | L6: 45951 | M6: 45952 | N6: 45953 | O6: 45954 | P6: 45955 | Q6: 45956 | R6: 45957 | S6: 45958 | T6: 45959 | U6: 45960 | V6: 45961 | W6: 45962 | X6: TOTAL
A7: 1 | B7: sdh dibyr lunas mggu lalu | C7: CC BRI Easy Card 5188 2802 8215 3601 (Based on billing tagihan bulan Okt) Tagihan Okt sudah dibayar | E7: 6352050 | F7: 22 OKT 2025 | X7: =SUM(H7:W7) -> 0
A8: 2 | B8: 5634050 | C8: CC DANAMON 5522 3923 4584 5175 dicicil 12x sdh dbyr 6x, bln ini sdh dbyr | E8: =167081785-B8 -> 161447735 | F8: 21 OKT 2025 | X8: =SUM(H8:W8) -> 0
A9: 3 | B9: =832665+835057 -> 1667722 | C9: CC HSBC 4034 0900 0329 0809 dicicil 36x sdh dbyr 4x @832.665 dicicil 36x sdh dbyr 4x @835.057 | E9: 26541476 | F9: 45958 | N9: =E9 -> 26541476 | X9: =SUM(H9:W9) -> 26541476
A10: 4 | B10: =2492006+103899 -> 2595905 | C10: CC HSBC 5183 2301 0213 6604 dicicil 36x sdh dibyr 4x @2,492,006 dicicil 4x sdh dibyr 4x @103,899 | E10: =60745985.546 -> 60745986 | F10: 45958 | N10: =B10 -> 2595905 | X10: =SUM(H10:W10) -> 2595905
A11: 5 | B11: =7518739+5406875 -> 12925614 | C11: CC DANAMON AMEX 3755 312077 38007 (dicicil 6x & sdh dbyr 3x) @7.518.739 dicicil 6x, sdh dbyr 1x @ 5.406.875, bln ini sudah dibayar | E11: =62783184-B11 -> 49857570 | F11: 45951 | X11: =SUM(H11:W11) -> 0
A12: 6 | C12: CC BRI PLATINUM 5520 0202 8322 8201, rencana bayar 13.764.854 | E12: 72553690 | F12: 45957 | N12: =E12 -> 72553690 | X12: =SUM(H12:W12) -> 72553690
A13: 7 | C13: CC DBS 4374-5600-0155-3448 rencana bayar 17.801.124 | E13: 21287550 | F13: 45932 | L13: 17801124 | X13: =SUM(H13:W13) -> 17801124
A14: 8 | C14: CC MANDIRI 4149 3130 0154 8958 Sdh dibyr tgl 07 Okt 2025 = 11.796.341 Akan dibyr lg tgl 21 Okt 25 = 18.101.721 | E14: =112039827-11796341 -> 100243486 | F14: 45938 | L14: 18101721 | X14: =SUM(H14:W14) -> 18101721
A15: 9 | C15: CC OCBC 4645 8311 0202 4628 Sdh dibyr tgl 02 Okt 25 = 5.040.126 | E15: =36348680-5040125 -> 31308555 | F15: 45936 | X15: =SUM(H15:W15) -> 0
A16: 10 | C16: CC DANAMON 3755 312163 39003 AMEX Sdh dibyr tgl 02 Okt 25 = 5.301.962 Akan dibyr lg tgl 21 Okt 25 = 15.178.135 | E16: =25057506-5301962 -> 19755544 | F16: 45935 | L16: 15178135 | X16: =SUM(H16:W16) -> 15178135
A17: 11 | C17: CC DANAMON 4258570913716109 INFINIT Sdh dibyr tgl 02 Okt 25 = 4.316.821 | E17: =13517654-4316821 -> 9200833 | F17: 45935 | X17: =SUM(H17:W17) -> 0
A18: 12 | C18: CC DANAMON 3567 9600 0500 0322 Sdh dibyr tgl 02 Okt 25 = 729.297 | E18: =12116411-729297 -> 11387114 | F18: 45935 | X18: =SUM(H18:W18) -> 0
A19: 13 | C19: CC MEGA 4201 9400 5250 1935 Sdh dibyr tgl 07 Okt 25 = 4.147.313 | E19: =50251214-414731 -> 49836483 | F19: 45940 | X19: =SUM(H19:W19) -> 0
A20: 14 | C20: CC MANDIRI 4137 1803 1348 6456 (Based on billing tagihan Okt 25) Tagihan Okt 25 sudah dibayar | E20: 2732885 | F20: 45941 | X20: =SUM(H20:W20) -> 0
A21: 15 | C21: CC MANDIRI 5126 7603 0309 4806 (Based on tagihan bulan Okt 2025) Tagihan Okt sudah dibayar | E21: 1440227 | F21: 45941 | X21: =SUM(H21:W21) -> 0
A22: 16 | C22: CC OCBC 5241 6955 0205 4757 (Based on tagihan bulan Okt 25) Tagihan Okt sudah dibayar | E22: 2793758 | F22: 45938 | X22: =SUM(H22:W22) -> 0
A23: 17 | C23: CC UOB 4219 2020 7256 0866 (Based on billing tagihan bln Okt 25) Tagihan Okt 25 sudah dibayar | E23: 2358430 | F23: 45935 | X23: =SUM(H23:W23) -> 0
A24: 18 | C24: CC CIMB 5463 1800 6037 0623 Sdh dibyr tgl 02 Okt 25 = 2.722.709 | E24: =24245918.57-2722709 -> 21523210 | F24: 45936 | X24: =SUM(H24:W24) -> 0
A25: 19 | C25: CC BNI CORP 4365 8300 0015 5888 (bln Okt 25 blm ada tagihan) | D25: Dita | E25: 0 | F25: 45939 | X25: =SUM(H25:W25) -> 0
A26: 20 | C26: CC BNI CORP 4365 8300 0015 5896 (based on billing tagihan Okt 25) Bln Okt 25 sudah dibayar tgl 09 Okt 25 | E26: 3079320 | F26: 45939 | X26: =SUM(H26:W26) -> 0
A27: 21 | C27: CC BNI CORP 4365 8300 0015 5904 (Based on Billing tagihan bulan Sept 25) Sdh dibyr bln Okt 25 = 88.383.689 | D27: Dimas | E27: =88383689 -> 88383689 | F27: 45939 | X27: =SUM(H27:W27) -> 0
A28: 22 | C28: CC BNI CORP 4365 8300 0015 5912 Sdh dibyr tgl 16 Okt 25 = 14.500.000 | E28: =34855152-14500000 -> 20355152 | F28: 45939 | X28: =SUM(H28:W28) -> 0
A29: 23 | C29: CC BNI CORP 4365 8300 0015 5961 Sdh dibyr tgl 14 Okt 25 = 22.842.460 | D29: Fadli | E29: =60217678-22842460 -> 37375218 | F29: 45939 | L29: 30526520 | S29: 7441198 | X29: =SUM(H29:W29) -> 37967718
A30: 24 | C30: CC BNI CORP 4365 8300 0015 5953 Blm ada tagihan CC bln Okt 25. | D30: Adiel | E30: 0 | F30: 45939 | X30: =SUM(H30:W30) -> 0
C31: Persiapan subscription (362 jt / tahun -> per bulan = 35 jt an) | E31: 35000000 | W31: 35000000 | X31: =SUM(H31:W31) -> 35000000
C32: WTM London : - tiket pesawat sdh masuk ek CC 100 jt - sisanya 74.636.000 | E32: 174636000 | M32: 74636000 | X32: =SUM(H32:W32) -> 74636000
C33: TOTAL | E33: =SUM(E7:E31) -> 8.3555996e+08 | H33: =SUM(H7:H32) -> 0 | I33: =SUM(I7:I32) -> 0 | J33: =SUM(J7:J32) -> 0 | K33: =SUM(K7:K32) -> 0 | L33: =SUM(L7:L32) -> 81607500 | M33: =SUM(M7:M32) -> 74636000 | N33: =SUM(N7:N32) -> 101691071 | O33: =SUM(O7:O32) -> 0 | ... X33: =SUM(X7:X32) -> 300375769

Sheet OUT - ACC - Ops Kantor
B1: Kategori : | C1: Cash Outflow (Pengeluaran Kas) | E1: Hari Kerja
B2: Pos Akun : | C2: Pengeluaran Operasional Kantor | E2: Jadwal Pembayaran (Selasa/ Jumat)
B3: Periode : | E3: Hari Libur
B4: Kategori : | C4: Cash Outflow (Pengeluaran Kas) | F4: Hari Kerja
B5: Pos Akun : | C5: Out-ACC-Ops | F5: Jadwal Pembayaran (Selasa/Kamis)
B6: Periode : | F6: Hari Libur
B7: Updated on : | C7: ='OUT - CFC - Bunga & Angsuran'!H4 -> 0 | D7: Pengeluaran Biaya Operating Sales & Marketing | E7: Pengeluaran Biaya Operating Sales & Marketing
D8: JUMAT | E8: SABTU | F8: MINGGU | G8: SENIN | H8: SELASA | I8: RABU | J8: KAMIS | K8: JUMAT | L8: SABTU | M8: MINGGU | N8: SENIN | O8: SELASA | P8: RABU | Q8: KAMIS | R8: JUMAT | S8: SABTU
A9: KETERANGAN | B9: NOMINAL | C9: TANGGAL | D9: 45947 | E9: 45948 | F9: 45949 | G9: 45950 | H9: 45951 | I9: 45952 | J9: 45953 | K9: 45954 | L9: 45955 | M9: 45956 | N9: 45957 | O9: 45958 | P9: 45959 | Q9: 45960 | R9: 45961 | S9: 45962 | T9: TOTAL
T10: =SUM(D10:S10) -> 0
T11: =SUM(D11:S11) -> 0
T12: =SUM(D12:S12) -> 0
T13: =SUM(D13:S13) -> 0
T14: =SUM(D14:S14) -> 0
T15: =SUM(D15:S15) -> 0
T16: =SUM(D16:S16) -> 0
T17: =SUM(D17:S17) -> 0
T18: =SUM(D18:S18) -> 0
T19: =SUM(D19:S19) -> 0
T20: =SUM(D20:S20) -> 0
B21: TOTAL BIAYA ACC | D21: =SUM(D10:D20) -> 0 | E21: =SUM(E10:E20) -> 0 | F21: =SUM(F10:F20) -> 0 | G21: =SUM(G10:G20) -> 0 | H21: =SUM(H10:H20) -> 0 | I21: =SUM(I10:I20) -> 0 | J21: =SUM(J10:J20) -> 0 | K21: =SUM(K10:K20) -> 0 | ... T21: =SUM(T10:T20) -> 0

Sheet OUT-ACS-OPS
B1: Kategori : | C1: Cash Outflow (Pengeluaran Kas) | F1: Hari Kerja
B2: Pos Akun : | C2: Out-ACS-Ops | F2: Jadwal Pembayaran (Selasa/ Kamis)
B3: Periode : | F3: Hari Libur
B4: Updated on : | C4: 45947 | D4: Pengeluaran Biaya Operating Sales & Marketing
D5: JUMAT | E5: SABTU | F5: MINGGU | G5: SENIN | H5: SELASA | I5: RABU | J5: KAMIS | K5: JUMAT | L5: SABTU | M5: MINGGU | N5: SENIN | O5: SELASA | P5: RABU | Q5: KAMIS | R5: JUMAT | S5: SABTU
A6: KETERANGAN | B6: NOMINAL | C6: TANGGAL | D6: 45947 | E6: 45948 | F6: 45949 | G6: 45950 | H6: 45951 | I6: 45952 | J6: 45953 | K6: 45954 | L6: 45955 | M6: 45956 | N6: 45957 | O6: 45958 | P6: 45959 | Q6: 45960 | R6: 45961 | S6: 45962 | T6: TOTAL
T7: =SUM(D7:S7) -> 0
T8: =SUM(D8:S8) -> 0
T9: =SUM(D9:S9) -> 0
T10: =SUM(D10:S10) -> 0
T11: =SUM(D11:S11) -> 0
T12: =SUM(D12:S12) -> 0
T13: =SUM(D13:S13) -> 0
T14: =SUM(D14:S14) -> 0
T15: =SUM(D15:S15) -> 0
T16: =SUM(D16:S16) -> 0
T17: =SUM(D17:S17) -> 0
B18: TOTAL BIAYA ACS | D18: =SUM(D7:D17) -> 0 | E18: =SUM(E7:E17) -> 0 | F18: =SUM(F7:F17) -> 0 | G18: =SUM(G7:G17) -> 0 | H18: =SUM(H7:H17) -> 0 | I18: =SUM(I7:I17) -> 0 | J18: =SUM(J7:J17) -> 0 | K18: =SUM(K7:K17) -> 0 | ... T18: =SUM(T7:T17) -> 0

Sheet OUT-BAS-OPS
B1: Kategori : | C1: Cash Outflow (Pengeluaran Kas) | F1: Hari Kerja
B2: Pos Akun : | C2: Out-Ops-BAS | F2: Jadwal Pembayaran (Selasa/ Kamis)
B3: Periode : | F3: Hari Libur
B4: Updated on : | C4: 45947 | D4: Pengeluaran Biaya Operating Sales & Marketing
D5: JUMAT | E5: SABTU | F5: MINGGU | G5: SENIN | H5: SELASA | I5: RABU | J5: KAMIS | K5: JUMAT | L5: SABTU | M5: MINGGU | N5: SENIN | O5: SELASA | P5: RABU | Q5: KAMIS | R5: JUMAT | S5: SABTU
A6: KETERANGAN | B6: NOMINAL | C6: TANGGAL | D6: 45947 | E6: 45948 | F6: 45949 | G6: 45950 | H6: 45951 | I6: 45952 | J6: 45953 | K6: 45954 | L6: 45955 | M6: 45956 | N6: 45957 | O6: 45958 | P6: 45959 | Q6: 45960 | R6: 45961 | S6: 45962 | T6: TOTAL
T7: =SUM(D7:S7) -> 0
T8: =SUM(D8:S8) -> 0
T9: =SUM(D9:S9) -> 0
T10: =SUM(D10:S10) -> 0
T11: =SUM(D11:S11) -> 0
T12: =SUM(D12:S12) -> 0
T13: =SUM(D13:S13) -> 0
T14: =SUM(D14:S14) -> 0
T15: =SUM(D15:S15) -> 0
T16: =SUM(D16:S16) -> 0
T17: =SUM(D17:S17) -> 0
B18: TOTAL BIAYA BAS | D18: =SUM(D7:D17) -> 0 | E18: =SUM(E7:E17) -> 0 | F18: =SUM(F7:F17) -> 0 | G18: =SUM(G7:G17) -> 0 | H18: =SUM(H7:H17) -> 0 | I18: =SUM(I7:I17) -> 0 | J18: =SUM(J7:J17) -> 0 | K18: =SUM(K7:K17) -> 0 | ... T18: =SUM(T7:T17) -> 0

Sheet OUT-BID-OPS
B1: Kategori : | C1: Cash Outflow (Pengeluaran Kas) | F1: Hari Kerja
B2: Pos Akun : | C2: OUT-BID-OPS | F2: Jadwal Pembayaran (Selasa/ Kamis)
B3: Periode : | F3: Hari Libur
B4: Updated on : | C4: 45947 | D4: Pengeluaran Biaya Operating Sales & Marketing
D5: JUMAT | E5: SABTU | F5: MINGGU | G5: SENIN | H5: SELASA | I5: RABU | J5: KAMIS | K5: JUMAT | L5: SABTU | M5: MINGGU | N5: SENIN | O5: SELASA | P5: RABU | Q5: KAMIS | R5: JUMAT | S5: SABTU
A6: HTANG PAJAK | B6: NOMINAL | C6: TANGGAL | D6: 45947 | E6: 45948 | F6: 45949 | G6: 45950 | H6: 45951 | I6: 45952 | J6: 45953 | K6: 45954 | L6: 45955 | M6: 45956 | N6: 45957 | O6: 45958 | P6: 45959 | Q6: 45960 | R6: 45961 | S6: 45962 | T6: TOTAL
T8: =SUM(D8:S8) -> 0
T9: =SUM(D9:S9) -> 0
T10: =SUM(D10:S10) -> 0
T11: =SUM(D11:S11) -> 0
B12: TOTAL | D12: =SUM(D8:D11) -> 0 | E12: =SUM(E8:E11) -> 0 | F12: =SUM(F8:F11) -> 0 | G12: =SUM(G8:G11) -> 0 | H12: =SUM(H8:H11) -> 0 | I12: =SUM(I8:I11) -> 0 | J12: =SUM(J8:J11) -> 0 | K12: =SUM(K8:K11) -> 0 | ... T12: =SUM(T8:T11) -> 0

Sheet OUT-CFC-OPS
B1: Kategori : | C1: Cash Outflow (Pengeluaran Kas) | F1: Hari Kerja
B2: Pos Akun : | C2: OUT-CFC-OPS | F2: Jadwal Pembayaran (Selasa/ Kamis)
B3: Periode : | F3: Hari Libur
B4: Updated on : | C4: 45947 | D4: Pengeluaran Biaya Operating Sales & Marketing
D5: JUMAT | E5: SABTU | F5: MINGGU | G5: SENIN | H5: SELASA | I5: RABU | J5: KAMIS | K5: JUMAT | L5: SABTU | M5: MINGGU | N5: SENIN | O5: SELASA | P5: RABU | Q5: KAMIS | R5: JUMAT | S5: SABTU
A6: HTANG PAJAK | B6: NOMINAL | C6: TANGGAL | D6: 45947 | E6: 45948 | F6: 45949 | G6: 45950 | H6: 45951 | I6: 45952 | J6: 45953 | K6: 45954 | L6: 45955 | M6: 45956 | N6: 45957 | O6: 45958 | P6: 45959 | Q6: 45960 | R6: 45961 | S6: 45962 | T6: TOTAL
T8: =SUM(D8:S8) -> 0
T9: =SUM(D9:S9) -> 0
T10: =SUM(D10:S10) -> 0
T11: =SUM(D11:S11) -> 0
B12: TOTAL | D12: =SUM(D8:D11) -> 0 | E12: =SUM(E8:E11) -> 0 | F12: =SUM(F8:F11) -> 0 | G12: =SUM(G8:G11) -> 0 | H12: =SUM(H8:H11) -> 0 | I12: =SUM(I8:I11) -> 0 | J12: =SUM(J8:J11) -> 0 | K12: =SUM(K8:K11) -> 0 | ... S12: =SUM(S8:S11) -> 0 | T12: =SUM(D12:S12) -> 0

Sheet OUT-GA-OPS
B1: Kategori : | C1: Cash Outflow (Pengeluaran Kas) | F1: Hari Kerja
B2: Pos Akun : | C2: OUT-GA-OPS | F2: Jadwal Pembayaran (Selasa/ Kamis)
B3: Periode : | F3: Hari Libur
B4: Updated on : | C4: 45947 | D4: Pengeluaran Biaya Operating Sales & Marketing
D5: JUMAT | E5: SABTU | F5: MINGGU | G5: SENIN | H5: SELASA | I5: RABU | J5: KAMIS | K5: JUMAT | L5: SABTU | M5: MINGGU | N5: SENIN | O5: SELASA | P5: RABU | Q5: KAMIS | R5: JUMAT | S5: SABTU
A6: HTANG PAJAK | B6: NOMINAL | C6: TANGGAL | D6: 45947 | E6: 45948 | F6: 45949 | G6: 45950 | H6: 45951 | I6: 45952 | J6: 45953 | K6: 45954 | L6: 45955 | M6: 45956 | N6: 45957 | O6: 45958 | P6: 45959 | Q6: 45960 | R6: 45961 | S6: 45962 | T6: TOTAL
A8: LISTRIK NOVEMBER | B8: 8000000 | O8: 8000000 | T8: =SUM(D8:S8) -> 8000000
A9: SEWA LAPANGAN BADMINTON | B9: 1200000 | H9: 1200000 | T9: =SUM(D9:S9) -> 1200000
A10: CATERING MAKAN SIANG | B10: 9000000 | H10: 4500000 | O10: 4500000 | T10: =SUM(D10:S10) -> 9000000
A11: BUAH | B11: 600000 | H11: 300000 | O11: 300000 | T11: =SUM(D11:S11) -> 600000
A12: ES BATU | B12: 80000 | H12: 40000 | O12: 40000 | T12: =SUM(D12:S12) -> 80000
A13: KADO FAREWELL | B13: 600000 | O13: 600000 | T13: =SUM(D13:S13) -> 600000
A14: KARANGAN BUNGA - TENTATIVE | B14: 1000000 | O14: 1000000 | T14: =SUM(D14:S14) -> 1000000
A15: PAJAK VARIO AB 4432 QI | B15: 300000 | J15: 300000 | T15: =SUM(D15:S15) -> 300000
A16: PAJAK VARIO AB 5523 KA | B16: 300000 | Q16: 300000 | T16: =SUM(D16:S16) -> 300000
A17: SERVICE POMPA WIPER | B17: 1000000 | O17: 1000000 | T17: =SUM(D17:S17) -> 1000000
A18: ASURANSI XPANDER | B18: 300000 | H18: 300000 | T18: =SUM(D18:S18) -> 300000
A19: SELANG WASTAFEL, FLASHER, SEALANT | B19: 300000 | O19: 300000 | T19: =SUM(D19:S19) -> 300000
A20: BBM MINGGUAN ZENIX & EXPANDER | B20: 600000 | H20: 600000 | T20: =SUM(D20:S20) -> 600000
A21: BBM GENSET | B21: 300000 | H21: 300000 | T21: =SUM(D21:S21) -> 300000
A22: PAKET FILTER WATER PURIFIER | B22: 2300000 | Q22: 2300000 | T22: =SUM(D22:S22) -> 2300000
A23: SELANG DAN CORONG VAKUM | B23: 660000 | H23: 660000 | T23: =SUM(D23:S23) -> 660000
T24: =SUM(D24:S24) -> 0
T25: =SUM(D25:S25) -> 0
B26: TOTAL | D26: =SUM(D8:D25) -> 0 | E26: =SUM(E8:E25) -> 0 | F26: =SUM(F8:F25) -> 0 | G26: =SUM(G8:G25) -> 0 | H26: =SUM(H8:H25) -> 7900000 | I26: =SUM(I8:I25) -> 0 | J26: =SUM(J8:J25) -> 300000 | K26: =SUM(K8:K25) -> 0 | ... S26: =SUM(S8:S25) -> 0 | T26: =SUM(D26:S26) -> 26540000

Sheet OUT-HR-OPS
B1: Kategori : | C1: Cash Outflow (Pengeluaran Kas) | F1: Hari Kerja
B2: Pos Akun : | C2: OUT-HR-OPS | F2: Jadwal Pembayaran (Selasa/ Kamis)
B3: Periode : | F3: Hari Libur
B4: Updated on : | C4: 45947 | D4: Pengeluaran Biaya Operating Sales & Marketing
D5: JUMAT | E5: SABTU | F5: MINGGU | G5: SENIN | H5: SELASA | I5: RABU | J5: KAMIS | K5: JUMAT | L5: SABTU | M5: MINGGU | N5: SENIN | O5: SELASA | P5: RABU | Q5: KAMIS | R5: JUMAT | S5: SABTU
A6: DESKRIPSI | B6: NOMINAL | C6: TANGGAL | D6: 45947 | E6: 45948 | F6: 45949 | G6: 45950 | H6: 45951 | I6: 45952 | J6: 45953 | K6: 45954 | L6: 45955 | M6: 45956 | N6: 45957 | O6: 45958 | P6: 45959 | Q6: 45960 | R6: 45961 | S6: 45962 | T6: TOTAL
A8: Training Branch Manager | B8: 5500000 | L8: 5500000 | T8: =SUM(D8:S8) -> 5500000
A9: CSR ke Darul Ullum by Lazismu | B9: 5000000 | O9: 5000000 | T9: =SUM(D9:S9) -> 5000000
A10: Posting lowongan di Glints | B10: 2000000 | J10: 2000000 | T10: =SUM(D10:S10) -> 2000000
A11: Posting lowongan di linkedIn (by CC) | B11: 2000000 | K11: 2000000 | T11: =SUM(D11:S11) -> 2000000
A12: Training Buttler for GA | B12: 2000000 | O12: 2000000 | T12: =SUM(D12:S12) -> 2000000
T13: =SUM(D13:S13) -> 0
T14: =SUM(D14:S14) -> 0
B15: TOTAL | D15: =SUM(D8:D14) -> 0 | E15: =SUM(E8:E14) -> 0 | F15: =SUM(F8:F14) -> 0 | G15: =SUM(G8:G14) -> 0 | H15: =SUM(H8:H14) -> 0 | I15: =SUM(I8:I14) -> 0 | J15: =SUM(J8:J14) -> 2000000 | K15: =SUM(K8:K14) -> 2000000 | ... S15: =SUM(S8:S14) -> 0 | T15: =SUM(D15:S15) -> 16500000

Sheet OUT-PD-OPS
B1: Kategori : | C1: Cash Outflow (Pengeluaran Kas) | F1: Hari Kerja
B2: Pos Akun : | C2: OUT-PD-OPS | F2: Jadwal Pembayaran (Selasa/ Kamis)
B3: Periode : | F3: Hari Libur
B4: Updated on : | C4: 45947 | D4: Pengeluaran Biaya Operating Sales & Marketing
D5: JUMAT | E5: SABTU | F5: MINGGU | G5: SENIN | H5: SELASA | I5: RABU | J5: KAMIS | K5: JUMAT | L5: SABTU | M5: MINGGU | N5: SENIN | O5: SELASA | P5: RABU | Q5: KAMIS | R5: JUMAT | S5: SABTU
A6: HTANG PAJAK | B6: NOMINAL | C6: TANGGAL | D6: 45947 | E6: 45948 | F6: 45949 | G6: 45950 | H6: 45951 | I6: 45952 | J6: 45953 | K6: 45954 | L6: 45955 | M6: 45956 | N6: 45957 | O6: 45958 | P6: 45959 | Q6: 45960 | R6: 45961 | S6: 45962 | T6: TOTAL
T8: =SUM(D8:S8) -> 0
T9: =SUM(D9:S9) -> 0
T10: =SUM(D10:S10) -> 0
T11: =SUM(D11:S11) -> 0
B12: TOTAL | D12: =SUM(D8:D11) -> 0 | E12: =SUM(E8:E11) -> 0 | F12: =SUM(F8:F11) -> 0 | G12: =SUM(G8:G11) -> 0 | H12: =SUM(H8:H11) -> 0 | I12: =SUM(I8:I11) -> 0 | J12: =SUM(J8:J11) -> 0 | K12: =SUM(K8:K11) -> 0 | ... S12: =SUM(S8:S11) -> 0 | T12: =SUM(D12:S12) -> 0

Sheet OUT-SS-OPS
B1: Kategori : | C1: Cash Outflow (Pengeluaran Kas) | F1: Hari Kerja
B2: Pos Akun : | C2: OUT-SS-OPS | F2: Jadwal Pembayaran (Selasa/ Kamis)
B3: Periode : | F3: Hari Libur
B4: Updated on : | C4: 45947 | D4: Pengeluaran Biaya Operating Sales & Marketing
D5: JUMAT | E5: SABTU | F5: MINGGU | G5: SENIN | H5: SELASA | I5: RABU | J5: KAMIS | K5: JUMAT | L5: SABTU | M5: MINGGU | N5: SENIN | O5: SELASA | P5: RABU | Q5: KAMIS | R5: JUMAT | S5: SABTU
A6: HTANG PAJAK | B6: NOMINAL | C6: TANGGAL | D6: 45947 | E6: 45948 | F6: 45949 | G6: 45950 | H6: 45951 | I6: 45952 | J6: 45953 | K6: 45954 | L6: 45955 | M6: 45956 | N6: 45957 | O6: 45958 | P6: 45959 | Q6: 45960 | R6: 45961 | S6: 45962 | T6: TOTAL
T8: =SUM(D8:S8) -> 0
T9: =SUM(D9:S9) -> 0
T10: =SUM(D10:S10) -> 0
T11: =SUM(D11:S11) -> 0
B12: TOTAL | D12: =SUM(D8:D11) -> 0 | E12: =SUM(E8:E11) -> 0 | F12: =SUM(F8:F11) -> 0 | G12: =SUM(G8:G11) -> 0 | H12: =SUM(H8:H11) -> 0 | I12: =SUM(I8:I11) -> 0 | J12: =SUM(J8:J11) -> 0 | K12: =SUM(K8:K11) -> 0 | ... S12: =SUM(S8:S11) -> 0 | T12: =SUM(D12:S12) -> 0

Sheet OUT-SO-OPS
B1: Kategori : | C1: Cash Outflow (Pengeluaran Kas) | F1: Hari Kerja
B2: Pos Akun : | C2: OUT-SO-OPS | F2: Jadwal Pembayaran (Selasa/ Kamis)
B3: Periode : | F3: Hari Libur
B4: Updated on : | C4: 45947 | D4: Pengeluaran Biaya Operating Sales & Marketing
D5: JUMAT | E5: SABTU | F5: MINGGU | G5: SENIN | H5: SELASA | I5: RABU | J5: KAMIS | K5: JUMAT | L5: SABTU | M5: MINGGU | N5: SENIN | O5: SELASA | P5: RABU | Q5: KAMIS | R5: JUMAT | S5: SABTU
A6: HTANG PAJAK | B6: NOMINAL | C6: TANGGAL | D6: 45947 | E6: 45948 | F6: 45949 | G6: 45950 | H6: 45951 | I6: 45952 | J6: 45953 | K6: 45954 | L6: 45955 | M6: 45956 | N6: 45957 | O6: 45958 | P6: 45959 | Q6: 45960 | R6: 45961 | S6: 45962 | T6: TOTAL
T8: =SUM(D8:S8) -> 0
T9: =SUM(D9:S9) -> 0
T10: =SUM(D10:S10) -> 0
T11: =SUM(D11:S11) -> 0
B12: TOTAL | D12: =SUM(D8:D11) -> 0 | E12: =SUM(E8:E11) -> 0 | F12: =SUM(F8:F11) -> 0 | G12: =SUM(G8:G11) -> 0 | H12: =SUM(H8:H11) -> 0 | I12: =SUM(I8:I11) -> 0 | J12: =SUM(J8:J11) -> 0 | K12: =SUM(K8:K11) -> 0 | ... S12: =SUM(S8:S11) -> 0 | T12: =SUM(D12:S12) -> 0

Sheet OUT-TEP-OPS
B1: Kategori : | C1: Cash Outflow (Pengeluaran Kas) | F1: Hari Kerja
B2: Pos Akun : | C2: OUT-TEP-OPS | F2: Jadwal Pembayaran (Selasa/ Kamis)
B3: Periode : | F3: Hari Libur
B4: Updated on : | C4: 45947 | D4: Pengeluaran Biaya Operating Sales & Marketing
D5: JUMAT | E5: SABTU | F5: MINGGU | G5: SENIN | H5: SELASA | I5: RABU | J5: KAMIS | K5: JUMAT | L5: SABTU | M5: MINGGU | N5: SENIN | O5: SELASA | P5: RABU | Q5: KAMIS | R5: JUMAT | S5: SABTU
A6: HTANG PAJAK | B6: NOMINAL | C6: TANGGAL | D6: 45947 | E6: 45948 | F6: 45949 | G6: 45950 | H6: 45951 | I6: 45952 | J6: 45953 | K6: 45954 | L6: 45955 | M6: 45956 | N6: 45957 | O6: 45958 | P6: 45959 | Q6: 45960 | R6: 45961 | S6: 45962 | T6: TOTAL
T8: =SUM(D8:S8) -> 0
T9: =SUM(D9:S9) -> 0
T10: =SUM(D10:S10) -> 0
T11: =SUM(D11:S11) -> 0
B12: TOTAL | D12: =SUM(D8:D11) -> 0 | E12: =SUM(E8:E11) -> 0 | F12: =SUM(F8:F11) -> 0 | G12: =SUM(G8:G11) -> 0 | H12: =SUM(H8:H11) -> 0 | I12: =SUM(I8:I11) -> 0 | J12: =SUM(J8:J11) -> 0 | K12: =SUM(K8:K11) -> 0 | ... S12: =SUM(S8:S11) -> 0 | T12: =SUM(D12:S12) -> 0

Sheet OUT-RESERVASI-OPS
B1: Kategori : | C1: Cash Outflow (Pengeluaran Kas) | F1: Hari Kerja
B2: Pos Akun : | C2: OUT-RESERVASI-OPS | F2: Jadwal Pembayaran (Selasa/ Kamis)
B3: Periode : | F3: Hari Libur
B4: Updated on : | C4: 45947 | D4: Pengeluaran Biaya Operating Sales & Marketing
D5: JUMAT | E5: SABTU | F5: MINGGU | G5: SENIN | H5: SELASA | I5: RABU | J5: KAMIS | K5: JUMAT | L5: SABTU | M5: MINGGU | N5: SENIN | O5: SELASA | P5: RABU | Q5: KAMIS | R5: JUMAT | S5: SABTU
A6: HTANG PAJAK | B6: NOMINAL | C6: TANGGAL | D6: 45947 | E6: 45948 | F6: 45949 | G6: 45950 | H6: 45951 | I6: 45952 | J6: 45953 | K6: 45954 | L6: 45955 | M6: 45956 | N6: 45957 | O6: 45958 | P6: 45959 | Q6: 45960 | R6: 45961 | S6: 45962 | T6: TOTAL
T8: =SUM(D8:S8) -> 0
T9: =SUM(D9:S9) -> 0
T10: =SUM(D10:S10) -> 0
T11: =SUM(D11:S11) -> 0
B12: TOTAL | D12: =SUM(D8:D11) -> 0 | E12: =SUM(E8:E11) -> 0 | F12: =SUM(F8:F11) -> 0 | G12: =SUM(G8:G11) -> 0 | H12: =SUM(H8:H11) -> 0 | I12: =SUM(I8:I11) -> 0 | J12: =SUM(J8:J11) -> 0 | K12: =SUM(K8:K11) -> 0 | ... S12: =SUM(S8:S11) -> 0 | T12: =SUM(D12:S12) -> 0

Sheet OUT-TAKSHAKA-OPS
B1: Kategori : | C1: Cash Outflow (Pengeluaran Kas) | F1: Hari Kerja
B2: Pos Akun : | C2: OUT-TAKSHAKA-OPS | F2: Jadwal Pembayaran (Selasa/ Kamis)
B3: Periode : | F3: Hari Libur
B4: Updated on : | C4: 45947 | D4: Pengeluaran Biaya Operating Sales & Marketing
D5: JUMAT | E5: SABTU | F5: MINGGU | G5: SENIN | H5: SELASA | I5: RABU | J5: KAMIS | K5: JUMAT | L5: SABTU | M5: MINGGU | N5: SENIN | O5: SELASA | P5: RABU | Q5: KAMIS | R5: JUMAT | S5: SABTU
A6: DESKRIPSI | B6: NOMINAL | C6: TANGGAL | D6: 45947 | E6: 45948 | F6: 45949 | G6: 45950 | H6: 45951 | I6: 45952 | J6: 45953 | K6: 45954 | L6: 45955 | M6: 45956 | N6: 45957 | O6: 45958 | P6: 45959 | Q6: 45960 | R6: 45961 | S6: 45962 | T6: TOTAL
T8: =SUM(D8:S8) -> 0
T9: =SUM(D9:S9) -> 0
T10: =SUM(D10:S10) -> 0
T11: =SUM(D11:S11) -> 0
B12: TOTAL | D12: =SUM(D8:D11) -> 0 | E12: =SUM(E8:E11) -> 0 | F12: =SUM(F8:F11) -> 0 | G12: =SUM(G8:G11) -> 0 | H12: =SUM(H8:H11) -> 0 | I12: =SUM(I8:I11) -> 0 | J12: =SUM(J8:J11) -> 0 | K12: =SUM(K8:K11) -> 0 | ... S12: =SUM(S8:S11) -> 0 | T12: =SUM(D12:S12) -> 0

Sheet OUT - CFC - Bunga & Angsuran
G1: Kategori : | H1: Cash Outflow (Pengeluaran Kas) | K1: Hari Kerja
G2: Pos Akun : | H2: Out-CFC-Pengeluaran Pembayaran Bunga & Angsuran | K2: Jadwal Pembayaran (Selasa/Kamis)
G3: Periode : | K3: Hari Libur
G4: Updated on : | H4: ='OUT - HR - Pemberian Pinjaman'!C4 -> 0 | I4: Pengeluaran Biaya Operating Sales & Marketing | J4: Pengeluaran Biaya Operating Sales & Marketing
I5: JUMAT | J5: SABTU | K5: MINGGU | L5: SENIN | M5: SELASA | N5: RABU | O5: KAMIS | P5: JUMAT | Q5: SABTU | R5: MINGGU | S5: SENIN | T5: SELASA | U5: RABU | V5: KAMIS | W5: JUMAT | X5: SABTU
A6: Nama Pos | B6: Bunga | C6: Pokok | D6: Nomor Kontrak | E6: Rekening Bank | F6: PERIODE PEMBAYARAN | G6: NOMINAL PEMBAYARAN | H6: TANGGAL | I6: 45947 | J6: 45948 | K6: 45949 | L6: 45950 | M6: 45951 | N6: 45952 | O6: 45953 | P6: 45954 | Q6: 45955 | R6: 45956 | S6: 45957 | T6: 45958 | U6: 45959 | V6: 45960 | W6: 45961 | X6: 45962 | Y6: TOTAL
A7: Biaya Bunga Pinjaman Modal Individu
A8: Biaya Bunga Pinjaman Modal BRI
F15: Total Biaya Bunga Modal Individu | I15: =SUM(I8:I14) -> 0 | J15: =SUM(J8:J14) -> 0 | K15: =SUM(K8:K14) -> 0 | L15: =SUM(L8:L14) -> 0 | M15: =SUM(M8:M14) -> 0 | N15: =SUM(N8:N14) -> 0 | O15: =SUM(O8:O14) -> 0 | P15: =SUM(P8:P14) -> 0 | ... Y15: =SUM(Y8:Y14) -> 0
A21: Biaya Bunga & Angsuran Pokok Kartu Kredit (Jika ada) | B21: Tgl Cetak | C21: Tgl Jatuh Tempo | D21: Tot Tagihan | E21: Min Payment | F21: Rencana Payment | G21: Sisa Tagihan | I21: 44711 | J21: 44712
G28: TOTAL BIAYA PEMBAYARAN RUTIN BUNGA & ANGSURAN | I28: =SUM(I22:I27) -> 0 | J28: =SUM(J22:J27) -> 0

Sheet OUT - TEP - Cost Of Revenue
C1: EXPENSES | D1: Kategori : | E1: Cash Outflow (Pengeluaran Kas) | H1: Hari Kerja
C2: 80% DP | D2: Pos Akun : | E2: OUT-TEP-COST OF REVENUE | H2: Jadwal Pembayaran (Selasa/ Kamis)
C3: 20% PEL | D3: Periode : | H3: Hari Libur
D4: Updated on : | E4: ='IN-ACC-Piutang & Revenue'!D4 -> 0 | F4: Pengeluaran Biaya Operating Sales & Marketing | G4: Pengeluaran Biaya Operating Sales & Marketing
H5: JUMAT | I5: SABTU | J5: MINGGU | K5: SENIN | L5: SELASA | M5: RABU | N5: KAMIS | O5: JUMAT | P5: SABTU | Q5: MINGGU | R5: SENIN | S5: SELASA | T5: RABU | U5: KAMIS | V5: JUMAT | W5: SABTU
